<?xml version="1.0"?>
<robot name="softsnake">
    <link name="world"/>
    <link name="base">
        <visual>
            <geometry>
                <box size="0.11 0.11 0.04"/>
            </geometry>
        <material name="silver">
            <color rgba="0.75 0.75 0.75 1"/>
        </material>
        <origin rpy="0 0 0" xyz="0 0 0.02"/>
        </visual>
    </link>
    <joint name="joint_base_fixed" type="fixed">
        <parent link="world"/>
        <child link="base"/>
    </joint>
    <link name="base_link">
        <visual>
            <geometry>
                <cylinder length="0.012" radius="0.05"/>
            </geometry>
        <material name="silver">
            <color rgba="0.75 0.75 0.75 1"/>
        </material>
        <!-- <origin rpy="0 0 0" xyz="0 0 0.046"/> -->
        </visual>
    </link>
    <joint name="joint_base_link" type="revolute">
        <axis xyz="0 0 1"/>
        <parent link="base"/>
        <child link="base_link"/>
        <limit effort="30" velocity="1.0" lower="-2.2" upper="0.7" />
        <origin rpy="0 0 0" xyz="0 0 0.046"/>
    </joint>
    <link name="sjoint1">
        <visual>
            <geometry>
                <box size = "0.002 0.035 0.025"/>
            </geometry>
        <material name="silver">
            <color rgba="0.75 0.75 0.75 1"/>
        </material>
        <origin rpy="0 0 0" xyz="0.035 0 0.0175"/>s
        </visual>
    </link>
    <joint name="sjoint_base1" type="fixed">
        <parent link="base_link"/>
        <child link="sjoint1"/>
    </joint>
    <link name="sjoint2">
        <visual>
            <geometry>
                <box size = "0.002 0.035 0.025"/>
            </geometry>
        <material name="silver">
            <color rgba="0.75 0.75 0.75 1"/>
        </material>
        <origin rpy="0 0 0" xyz="-0.035 0 0.0175"/>
        </visual>
    </link>
    <joint name="sjoint_base2" type="fixed">
        <parent link="base_link"/>
        <child link="sjoint2"/>
    </joint>
    <link name="joint1_link">
        <visual>
            <geometry>
                <box size = "0.07 0.015 0.15"/>
            </geometry>
        <material name="silver">
            <color rgba="0.75 0.75 0.75 1"/>
        </material>
        <origin rpy="0 0 0" xyz="0 0 0.08"/>
        </visual>
    </link>
    <joint name="joint1_link" type="revolute">
        <axis xyz="1 0 0"/>
        <parent link="base_link"/>
        <child link="joint1_link"/>
        <limit effort="30" velocity="1.0" lower="-1.5" upper="1.5" />
        <origin rpy="0 0 0" xyz="0 0 0.0125"/>
    </joint>
     <link name="joint2_link">
        <visual>
            <geometry>
                <box size = "0.07 0.015 0.18"/>
            </geometry>
        <material name="silver">
            <color rgba="0.75 0.75 0.75 1"/>
        </material>
        <origin rpy="0 0 0" xyz="0 0 0.08"/>
        </visual>
    </link>
    <joint name="joint2_link" type="revolute">
        <axis xyz="1 0 0"/>
        <parent link="joint1_link"/>
        <child link="joint2_link"/>
        <limit effort="30" velocity="1.0" lower="-1.5" upper="1.5" />
        <origin rpy="0 0 0" xyz="0 0 0.14"/>
    </joint>
    <link name="joint3_link">
        <visual>
            <geometry>
                <box size = "0.07 0.015 0.065"/>
            </geometry>
        <material name="silver">
            <color rgba="0.75 0.75 0.75 1"/>
        </material>
        <origin rpy="0 0 0" xyz="0 0 0.025"/>
        </visual>
    </link>
    <joint name="joint3_link" type="revolute">
        <axis xyz="1 0 0"/>
        <parent link="joint2_link"/>
        <child link="joint3_link"/>
        <limit effort="30" velocity="1.0" lower="-1.5" upper="1.5" />
        <origin rpy="0 0 0" xyz="0 0 0.15"/>
    </joint>
</robot>